Workbook
Name AvanceTbl: Config!$B$6:$C$9
Name EstadoCambioList: Config!$G$13:$G$16
Name EstadoList: Config!$B$6:$B$9
Name EstadoNCList: Config!$E$13:$E$16
Name SeveridadList: Config!$B$13:$B$15
Name TableroList: Config!$J$5:$J$10

Sheet Resumen
B2: RESUMEN GENERAL — INTEGRACIÓN DE TABLEROS
B3: Consolidado automático. Fechas plan cargadas desde la carta Gantt del proveedor.
B5: Tablero | C5: Avance Global | D5: Estado General | E5: Plan Inicio | F5: Plan Fin Despacho | G5: Real Fin Despacho | H5: NC Abiertas | I5: Cambios Pend.
B6: TP | C6: =TP!$G$7 -> 0.36494253 | D6: =IF(C6>=1,"Completado",IF(C6>=0.99,"Por liberar",IF(C6>0,"En proceso","No iniciado"))) -> En proceso | E6: =TP!$G$10 -> 46237 | F6: =TP!$H$52 -> 46271 | G6: =TP!$J$55 -> 0 | H6: =COUNTIFS(NoConformidades!$B:$B,B6,NoConformidades!$G:$G,"<>Cerrada") -> 0 | I6: =COUNTIFS(ControlCambios!$C:$C,B6,ControlCambios!$G:$G,"Propuesto") -> 0
B7: T_G2 | C7: =T_G2!$G$7 -> 0.36494253 | D7: =IF(C7>=1,"Completado",IF(C7>=0.99,"Por liberar",IF(C7>0,"En proceso","No iniciado"))) -> En proceso | E7: =T_G2!$G$10 -> 46237 | F7: =T_G2!$H$52 -> 46271 | G7: =T_G2!$J$55 -> 0 | H7: =COUNTIFS(NoConformidades!$B:$B,B7,NoConformidades!$G:$G,"<>Cerrada") -> 0 | I7: =COUNTIFS(ControlCambios!$C:$C,B7,ControlCambios!$G:$G,"Propuesto") -> 0
B8: BUS_A | C8: =BUS_A!$G$7 -> 0.51785714 | D8: =IF(C8>=1,"Completado",IF(C8>=0.99,"Por liberar",IF(C8>0,"En proceso","No iniciado"))) -> En proceso | E8: =BUS_A!$G$10 -> 46237 | F8: =BUS_A!$H$52 -> 46286 | G8: =BUS_A!$J$55 -> 0 | H8: =COUNTIFS(NoConformidades!$B:$B,B8,NoConformidades!$G:$G,"<>Cerrada") -> 0 | I8: =COUNTIFS(ControlCambios!$C:$C,B8,ControlCambios!$G:$G,"Propuesto") -> 0
B9: BUS_B | C9: =BUS_B!$G$7 -> 0.51785714 | D9: =IF(C9>=1,"Completado",IF(C9>=0.99,"Por liberar",IF(C9>0,"En proceso","No iniciado"))) -> En proceso | E9: =BUS_B!$G$10 -> 46237 | F9: =BUS_B!$H$52 -> 46286 | G9: =BUS_B!$J$55 -> 0 | H9: =COUNTIFS(NoConformidades!$B:$B,B9,NoConformidades!$G:$G,"<>Cerrada") -> 0 | I9: =COUNTIFS(ControlCambios!$C:$C,B9,ControlCambios!$G:$G,"Propuesto") -> 0
B10: CLIMA_A | C10: =CLIMA_A!$G$7 -> 0.44836957 | D10: =IF(C10>=1,"Completado",IF(C10>=0.99,"Por liberar",IF(C10>0,"En proceso","No iniciado"))) -> En proceso | E10: =CLIMA_A!$G$10 -> 46237 | F10: =CLIMA_A!$H$52 -> 46271 | G10: =CLIMA_A!$J$55 -> 0 | H10: =COUNTIFS(NoConformidades!$B:$B,B10,NoConformidades!$G:$G,"<>Cerrada") -> 0 | I10: =COUNTIFS(ControlCambios!$C:$C,B10,ControlCambios!$G:$G,"Propuesto") -> 0
B11: CLIMA_B | C11: =CLIMA_B!$G$7 -> 0.44836957 | D11: =IF(C11>=1,"Completado",IF(C11>=0.99,"Por liberar",IF(C11>0,"En proceso","No iniciado"))) -> En proceso | E11: =CLIMA_B!$G$10 -> 46237 | F11: =CLIMA_B!$H$52 -> 46271 | G11: =CLIMA_B!$J$55 -> 0 | H11: =COUNTIFS(NoConformidades!$B:$B,B11,NoConformidades!$G:$G,"<>Cerrada") -> 0 | I11: =COUNTIFS(ControlCambios!$C:$C,B11,ControlCambios!$G:$G,"Propuesto") -> 0
B12: PROMEDIO / TOTAL | C12: =AVERAGE(C6:C11) -> 0.44372308 | H12: =SUM(H6:H11) -> 0 | I12: =SUM(I6:I11) -> 0
B15: Leyenda estados (sub-hitos):
B16: Pendiente = 0% | C16: En proceso = 50% | D16: Completado = 100%

Sheet TP
B2: SEGUIMIENTO DE INTEGRACIÓN — TABLERO TP
B4: Proyecto: | C4: REMODELACIÓN CENTRO DE DATOS MAGNUS 1 | F4: TAG: | G4: TP | I4: Rev.:
B5: Fabricante: | C5: CMF | F5: OC/Contrato: | G5: IN-17248 | I5: Actualizado: | J5: 46234
B7: AVANCE GLOBAL DEL TABLERO | G7: =IFERROR(($D10*$F10+$D16*$F16+$D23*$F23+$D30*$F30+$D37*$F37+$D43*$F43+$D47*$F47+$D52*$F52)/($D10+$D16+$D23+$D30+$D37+$D43+$D47+$D52),0) -> 0.36494253
B9: # | C9: Hito / Sub-actividad | D9: Peso | E9: Estado | F9: Avance | G9: Plan Inicio | H9: Plan Fin | I9: Real Inicio | J9: Real Fin | K9: Responsable | L9: Observaciones
C10: 1. Armado de Tablero | D10: =SUMIF($E11:$E15,"<>N/A",$D11:$D15) -> 11 | F10: {=IFERROR(SUMPRODUCT(($E11:$E15<>"N/A")*$D11:$D15,IF($E11:$E15="N/A",0,$F11:$F15))/$D10,0)} -> 0.70454545 | G10: 46237 | H10: 46240 | I10: 46203 | J10: 46211
B11: 1.1 | C11: Recepción y verificación de envolvente (dimensiones, IP/IK, RAL) | D11: 1.5 | E11: Completado | F11: =IF($E11="N/A","",VLOOKUP($E11,AvanceTbl,2,FALSE())) -> 1 | K11: CSE
B12: 1.2 | C12: Ensamble de estructura y paneles del gabinete | D12: 5 | E12: Completado | F12: =IF($E12="N/A","",VLOOKUP($E12,AvanceTbl,2,FALSE())) -> 1 | K12: CMF
B13: 1.3 | C13: Montaje de perfilería DIN y placas de montaje | D13: 4 | E13: N/A | F13: =IF($E13="N/A","",VLOOKUP($E13,AvanceTbl,2,FALSE())) | K13: CMF
B14: 1.4 | C14: Instalación de puertas, bisagras y cerraduras | D14: 2 | E14: Pendiente | F14: =IF($E14="N/A","",VLOOKUP($E14,AvanceTbl,2,FALSE())) -> 0 | K14: CMF
B15: 1.5 | C15: Fijación de canaletas y sistema de cableado | D15: 2.5 | E15: En proceso | F15: =IF($E15="N/A","",VLOOKUP($E15,AvanceTbl,2,FALSE())) -> 0.5 | K15: CSE
C16: 2. Montaje de protecciones | D16: =SUMIF($E17:$E22,"<>N/A",$D17:$D22) -> 7 | F16: {=IFERROR(SUMPRODUCT(($E17:$E22<>"N/A")*$D17:$D22,IF($E17:$E22="N/A",0,$F17:$F22))/$D16,0)} -> 0.75 | G16: 46259 | H16: 46260
B17: 2.1 | C17: Verificación de aparatos vs. lista de materiales (marca/In/Icu) | D17: 1.5 | E17: Completado | F17: =IF($E17="N/A","",VLOOKUP($E17,AvanceTbl,2,FALSE())) -> 1 | K17: CSE
B18: 2.2 | C18: Montaje de interruptor principal | D18: 3 | E18: Completado | F18: =IF($E18="N/A","",VLOOKUP($E18,AvanceTbl,2,FALSE())) -> 1 | K18: CMF
B19: 2.3 | C19: Montaje de protecciones de derivación | D19: 3 | E19: N/A | F19: =IF($E19="N/A","",VLOOKUP($E19,AvanceTbl,2,FALSE())) | K19: CMF
B20: 2.4 | C20: Montaje de diferenciales / protecciones auxiliares | D20: 2 | E20: N/A | F20: =IF($E20="N/A","",VLOOKUP($E20,AvanceTbl,2,FALSE())) | K20: CMF
B21: 2.5 | C21: Instalación de instrumentación (medidores, TC, relés) | D21: 1.5 | E21: En proceso | F21: =IF($E21="N/A","",VLOOKUP($E21,AvanceTbl,2,FALSE())) -> 0.5 | K21: CMF
B22: 2.6 | C22: Fijación y torque de aparatos según layout | D22: 1 | E22: Pendiente | F22: =IF($E22="N/A","",VLOOKUP($E22,AvanceTbl,2,FALSE())) -> 0 | K22: CMF
C23: 3. Fabricación y montaje de barras | D23: =SUMIF($E24:$E29,"<>N/A",$D24:$D29) -> 28 | F23: {=IFERROR(SUMPRODUCT(($E24:$E29<>"N/A")*$D24:$D29,IF($E24:$E29="N/A",0,$F24:$F29))/$D23,0)} -> 0.5 | G23: 46259 | H23: 46260
B24: 3.1 | C24: Corte y conformado de barras (fases, N) | D24: 8 | E24: En proceso | F24: =IF($E24="N/A","",VLOOKUP($E24,AvanceTbl,2,FALSE())) -> 0.5 | K24: CMF
B25: 3.2 | C25: Perforado y tratamiento de superficie / aislamiento | D25: 8 | E25: En proceso | F25: =IF($E25="N/A","",VLOOKUP($E25,AvanceTbl,2,FALSE())) -> 0.5 | K25: CMF
B26: 3.3 | C26: Montaje de aisladores y soportes de barra | D26: 4 | E26: Completado | F26: =IF($E26="N/A","",VLOOKUP($E26,AvanceTbl,2,FALSE())) -> 1 | K26: CMF
B27: 3.4 | C27: Instalación de barras principales con torque especificado | D27: 4 | E27: En proceso | F27: =IF($E27="N/A","",VLOOKUP($E27,AvanceTbl,2,FALSE())) -> 0.5 | K27: CMF
B28: 3.5 | C28: Montaje de barra de tierra (PE) y neutro (N) | D28: 2 | E28: Pendiente | F28: =IF($E28="N/A","",VLOOKUP($E28,AvanceTbl,2,FALSE())) -> 0 | K28: CMF
B29: 3.6 | C29: Conexión de derivaciones a protecciones | D29: 2 | E29: Pendiente | F29: =IF($E29="N/A","",VLOOKUP($E29,AvanceTbl,2,FALSE())) -> 0 | K29: CMF
C30: 4. Alambrado del tablero | D30: =SUMIF($E31:$E36,"<>N/A",$D31:$D36) -> 14 | F30: {=IFERROR(SUMPRODUCT(($E31:$E36<>"N/A")*$D31:$D36,IF($E31:$E36="N/A",0,$F31:$F36))/$D30,0)} -> 0.28571429 | G30: 46262 | H30: 46266
B31: 4.1 | C31: Alambrado de circuito de fuerza | D31: 4 | E31: N/A | F31: =IF($E31="N/A","",VLOOKUP($E31,AvanceTbl,2,FALSE())) | K31: CMF
B32: 4.2 | C32: Alambrado de circuito de control / mando | D32: 3 | E32: En proceso | F32: =IF($E32="N/A","",VLOOKUP($E32,AvanceTbl,2,FALSE())) -> 0.5 | K32: CMF
B33: 4.3 | C33: Conexionado de instrumentación y señalización | D33: 2 | E33: Pendiente | F33: =IF($E33="N/A","",VLOOKUP($E33,AvanceTbl,2,FALSE())) -> 0 | K33: CMF
B34: 4.4 | C34: Montaje de punteras/terminales y apriete con torque | D34: 5 | E34: En proceso | F34: =IF($E34="N/A","",VLOOKUP($E34,AvanceTbl,2,FALSE())) -> 0.5 | K34: CMF
B35: 4.5 | C35: Peinado y ordenamiento de mazos de cable | D35: 2 | E35: Pendiente | F35: =IF($E35="N/A","",VLOOKUP($E35,AvanceTbl,2,FALSE())) -> 0 | K35: CMF
B36: 4.6 | C36: Conexión de barra PE a partes metálicas accesibles | D36: 2 | E36: Pendiente | F36: =IF($E36="N/A","",VLOOKUP($E36,AvanceTbl,2,FALSE())) -> 0 | K36: CMF
C37: 5. Rotulación | D37: =SUMIF($E38:$E42,"<>N/A",$D38:$D42) -> 5 | F37: {=IFERROR(SUMPRODUCT(($E38:$E42<>"N/A")*$D38:$D42,IF($E38:$E42="N/A",0,$F38:$F42))/$D37,0)} -> 0.15 | G37: 46267 | H37: 46267
B38: 5.1 | C38: Etiquetado de conductores en ambos extremos | D38: 1.5 | E38: En proceso | F38: =IF($E38="N/A","",VLOOKUP($E38,AvanceTbl,2,FALSE())) -> 0.5 | K38: CMF
B39: 5.2 | C39: Rotulado de aparatos y bornes según planos | D39: 1.5 | E39: Pendiente | F39: =IF($E39="N/A","",VLOOKUP($E39,AvanceTbl,2,FALSE())) -> 0 | K39: CMF
B40: 5.3 | C40: Instalación de placa de características (nameplate) | D40: 0.5 | E40: Pendiente | F40: =IF($E40="N/A","",VLOOKUP($E40,AvanceTbl,2,FALSE())) -> 0 | K40: CMF
B41: 5.4 | C41: Rótulos de advertencia y seguridad | D41: 0.5 | E41: Pendiente | F41: =IF($E41="N/A","",VLOOKUP($E41,AvanceTbl,2,FALSE())) -> 0 | K41: CMF
B42: 5.5 | C42: Verificación de coincidencia rótulos vs. esquema | D42: 1 | E42: Pendiente | F42: =IF($E42="N/A","",VLOOKUP($E42,AvanceTbl,2,FALSE())) -> 0 | K42: CSE
C43: 6. Pruebas FAT | D43: =SUMIF($E44:$E46,"<>N/A",$D44:$D46) -> 10 | F43: {=IFERROR(SUMPRODUCT(($E44:$E46<>"N/A")*$D44:$D46,IF($E44:$E46="N/A",0,$F44:$F46))/$D43,0)} -> 0 | G43: 46267 | H43: 46267
B44: 6.1 | C44: Ejecución de protocolo FAT (según alcance definido) | D44: 5 | E44: Pendiente | F44: =IF($E44="N/A","",VLOOKUP($E44,AvanceTbl,2,FALSE())) -> 0 | K44: CMF
...

Sheet T_G2
B2: SEGUIMIENTO DE INTEGRACIÓN — TABLERO T_G2
B4: Proyecto: | C4: REMODELACIÓN CENTRO DE DATOS MAGNUS 1 | F4: TAG: | G4: T_G2 | I4: Rev.:
B5: Fabricante: | C5: CMF | F5: C.Costo | G5: IN-17428 | I5: Actualizado: | J5: 46234
B7: AVANCE GLOBAL DEL TABLERO | G7: =IFERROR(($D10*$F10+$D16*$F16+$D23*$F23+$D30*$F30+$D37*$F37+$D43*$F43+$D47*$F47+$D52*$F52)/($D10+$D16+$D23+$D30+$D37+$D43+$D47+$D52),0) -> 0.36494253
B9: # | C9: Hito / Sub-actividad | D9: Peso | E9: Estado | F9: Avance | G9: Plan Inicio | H9: Plan Fin | I9: Real Inicio | J9: Real Fin | K9: Responsable | L9: Observaciones
C10: 1. Armado de Tablero | D10: =SUMIF($E11:$E15,"<>N/A",$D11:$D15) -> 11 | F10: {=IFERROR(SUMPRODUCT(($E11:$E15<>"N/A")*$D11:$D15,IF($E11:$E15="N/A",0,$F11:$F15))/$D10,0)} -> 0.70454545 | G10: 46237 | H10: 46240 | I10: 46203 | J10: 46211
B11: 1.1 | C11: Recepción y verificación de envolvente (dimensiones, IP/IK, RAL) | D11: 1.5 | E11: Completado | F11: =IF($E11="N/A","",VLOOKUP($E11,AvanceTbl,2,FALSE())) -> 1 | K11: CSE
B12: 1.2 | C12: Ensamble de estructura y paneles del gabinete | D12: 5 | E12: Completado | F12: =IF($E12="N/A","",VLOOKUP($E12,AvanceTbl,2,FALSE())) -> 1 | K12: CMF
B13: 1.3 | C13: Montaje de perfilería DIN y placas de montaje | D13: 4 | E13: N/A | F13: =IF($E13="N/A","",VLOOKUP($E13,AvanceTbl,2,FALSE())) | K13: CMF
B14: 1.4 | C14: Instalación de puertas, bisagras y cerraduras | D14: 2 | E14: Pendiente | F14: =IF($E14="N/A","",VLOOKUP($E14,AvanceTbl,2,FALSE())) -> 0 | K14: CMF
B15: 1.5 | C15: Fijación de canaletas y sistema de cableado | D15: 2.5 | E15: En proceso | F15: =IF($E15="N/A","",VLOOKUP($E15,AvanceTbl,2,FALSE())) -> 0.5 | K15: CSE
C16: 2. Montaje de protecciones | D16: =SUMIF($E17:$E22,"<>N/A",$D17:$D22) -> 7 | F16: {=IFERROR(SUMPRODUCT(($E17:$E22<>"N/A")*$D17:$D22,IF($E17:$E22="N/A",0,$F17:$F22))/$D16,0)} -> 0.75 | G16: 46259 | H16: 46260 | I16: 46206
B17: 2.1 | C17: Verificación de aparatos vs. lista de materiales (marca/In/Icu) | D17: 1.5 | E17: Completado | F17: =IF($E17="N/A","",VLOOKUP($E17,AvanceTbl,2,FALSE())) -> 1 | K17: CSE
B18: 2.2 | C18: Montaje de interruptor principal | D18: 3 | E18: Completado | F18: =IF($E18="N/A","",VLOOKUP($E18,AvanceTbl,2,FALSE())) -> 1 | K18: CMF
B19: 2.3 | C19: Montaje de protecciones de derivación | D19: 3 | E19: N/A | F19: =IF($E19="N/A","",VLOOKUP($E19,AvanceTbl,2,FALSE())) | K19: CMF
B20: 2.4 | C20: Montaje de diferenciales / protecciones auxiliares | D20: 2 | E20: N/A | F20: =IF($E20="N/A","",VLOOKUP($E20,AvanceTbl,2,FALSE())) | K20: CMF
B21: 2.5 | C21: Instalación de instrumentación (medidores, TC, relés) | D21: 1.5 | E21: En proceso | F21: =IF($E21="N/A","",VLOOKUP($E21,AvanceTbl,2,FALSE())) -> 0.5 | K21: CMF
B22: 2.6 | C22: Fijación y torque de aparatos según layout | D22: 1 | E22: Pendiente | F22: =IF($E22="N/A","",VLOOKUP($E22,AvanceTbl,2,FALSE())) -> 0 | K22: CMF
C23: 3. Fabricación y montaje de barras | D23: =SUMIF($E24:$E29,"<>N/A",$D24:$D29) -> 28 | F23: {=IFERROR(SUMPRODUCT(($E24:$E29<>"N/A")*$D24:$D29,IF($E24:$E29="N/A",0,$F24:$F29))/$D23,0)} -> 0.5 | G23: 46259 | H23: 46260
B24: 3.1 | C24: Corte y conformado de barras (fases, N) | D24: 8 | E24: En proceso | F24: =IF($E24="N/A","",VLOOKUP($E24,AvanceTbl,2,FALSE())) -> 0.5 | K24: CMF
B25: 3.2 | C25: Perforado y tratamiento de superficie / aislamiento | D25: 8 | E25: En proceso | F25: =IF($E25="N/A","",VLOOKUP($E25,AvanceTbl,2,FALSE())) -> 0.5 | K25: CMF
B26: 3.3 | C26: Montaje de aisladores y soportes de barra | D26: 4 | E26: Completado | F26: =IF($E26="N/A","",VLOOKUP($E26,AvanceTbl,2,FALSE())) -> 1 | K26: CMF
B27: 3.4 | C27: Instalación de barras principales con torque especificado | D27: 4 | E27: En proceso | F27: =IF($E27="N/A","",VLOOKUP($E27,AvanceTbl,2,FALSE())) -> 0.5 | K27: CMF
B28: 3.5 | C28: Montaje de barra de tierra (PE) y neutro (N) | D28: 2 | E28: Pendiente | F28: =IF($E28="N/A","",VLOOKUP($E28,AvanceTbl,2,FALSE())) -> 0 | K28: CMF
B29: 3.6 | C29: Conexión de derivaciones a protecciones | D29: 2 | E29: Pendiente | F29: =IF($E29="N/A","",VLOOKUP($E29,AvanceTbl,2,FALSE())) -> 0 | K29: CMF
C30: 4. Alambrado del tablero | D30: =SUMIF($E31:$E36,"<>N/A",$D31:$D36) -> 14 | F30: {=IFERROR(SUMPRODUCT(($E31:$E36<>"N/A")*$D31:$D36,IF($E31:$E36="N/A",0,$F31:$F36))/$D30,0)} -> 0.28571429 | G30: 46262 | H30: 46266
B31: 4.1 | C31: Alambrado de circuito de fuerza | D31: 4 | E31: N/A | F31: =IF($E31="N/A","",VLOOKUP($E31,AvanceTbl,2,FALSE())) | K31: CMF
B32: 4.2 | C32: Alambrado de circuito de control / mando | D32: 3 | E32: En proceso | F32: =IF($E32="N/A","",VLOOKUP($E32,AvanceTbl,2,FALSE())) -> 0.5 | K32: CMF
B33: 4.3 | C33: Conexionado de instrumentación y señalización | D33: 2 | E33: Pendiente | F33: =IF($E33="N/A","",VLOOKUP($E33,AvanceTbl,2,FALSE())) -> 0 | K33: CMF
B34: 4.4 | C34: Montaje de punteras/terminales y apriete con torque | D34: 5 | E34: En proceso | F34: =IF($E34="N/A","",VLOOKUP($E34,AvanceTbl,2,FALSE())) -> 0.5 | K34: CMF
B35: 4.5 | C35: Peinado y ordenamiento de mazos de cable | D35: 2 | E35: Pendiente | F35: =IF($E35="N/A","",VLOOKUP($E35,AvanceTbl,2,FALSE())) -> 0 | K35: CMF
B36: 4.6 | C36: Conexión de barra PE a partes metálicas accesibles | D36: 2 | E36: Pendiente | F36: =IF($E36="N/A","",VLOOKUP($E36,AvanceTbl,2,FALSE())) -> 0 | K36: CMF
C37: 5. Rotulación | D37: =SUMIF($E38:$E42,"<>N/A",$D38:$D42) -> 5 | F37: {=IFERROR(SUMPRODUCT(($E38:$E42<>"N/A")*$D38:$D42,IF($E38:$E42="N/A",0,$F38:$F42))/$D37,0)} -> 0.15 | G37: 46267 | H37: 46267
B38: 5.1 | C38: Etiquetado de conductores en ambos extremos | D38: 1.5 | E38: En proceso | F38: =IF($E38="N/A","",VLOOKUP($E38,AvanceTbl,2,FALSE())) -> 0.5 | K38: CMF
B39: 5.2 | C39: Rotulado de aparatos y bornes según planos | D39: 1.5 | E39: Pendiente | F39: =IF($E39="N/A","",VLOOKUP($E39,AvanceTbl,2,FALSE())) -> 0 | K39: CMF
B40: 5.3 | C40: Instalación de placa de características (nameplate) | D40: 0.5 | E40: Pendiente | F40: =IF($E40="N/A","",VLOOKUP($E40,AvanceTbl,2,FALSE())) -> 0 | K40: CMF
B41: 5.4 | C41: Rótulos de advertencia y seguridad | D41: 0.5 | E41: Pendiente | F41: =IF($E41="N/A","",VLOOKUP($E41,AvanceTbl,2,FALSE())) -> 0 | K41: CMF
B42: 5.5 | C42: Verificación de coincidencia rótulos vs. esquema | D42: 1 | E42: Pendiente | F42: =IF($E42="N/A","",VLOOKUP($E42,AvanceTbl,2,FALSE())) -> 0 | K42: CSE
C43: 6. Pruebas FAT | D43: =SUMIF($E44:$E46,"<>N/A",$D44:$D46) -> 10 | F43: {=IFERROR(SUMPRODUCT(($E44:$E46<>"N/A")*$D44:$D46,IF($E44:$E46="N/A",0,$F44:$F46))/$D43,0)} -> 0 | G43: 46267 | H43: 46267
B44: 6.1 | C44: Ejecución de protocolo FAT (según alcance definido) | D44: 5 | E44: Pendiente | F44: =IF($E44="N/A","",VLOOKUP($E44,AvanceTbl,2,FALSE())) -> 0 | K44: CMF
...

Sheet BUS_A
B2: SEGUIMIENTO DE INTEGRACIÓN — TABLERO BUS_A
B4: Proyecto: | C4: REMODELACIÓN CENTRO DE DATOS MAGNUS 1 | F4: TAG: | G4: BUS_A | I4: Rev.:
B5: Fabricante: | C5: CMF | F5: OC/Contrato: | I5: Actualizado: | J5: 46234
B7: AVANCE GLOBAL DEL TABLERO | G7: =IFERROR(($D10*$F10+$D16*$F16+$D23*$F23+$D30*$F30+$D37*$F37+$D43*$F43+$D47*$F47+$D52*$F52)/($D10+$D16+$D23+$D30+$D37+$D43+$D47+$D52),0) -> 0.51785714
B9: # | C9: Hito / Sub-actividad | D9: Peso | E9: Estado | F9: Avance | G9: Plan Inicio | H9: Plan Fin | I9: Real Inicio | J9: Real Fin | K9: Responsable | L9: Observaciones
C10: 1. Armado de Tablero | D10: =SUMIF($E11:$E15,"<>N/A",$D11:$D15) -> 15 | F10: {=IFERROR(SUMPRODUCT(($E11:$E15<>"N/A")*$D11:$D15,IF($E11:$E15="N/A",0,$F11:$F15))/$D10,0)} -> 0.71666667 | G10: 46237 | H10: 46240 | I10: 46203 | J10: 46211
B11: 1.1 | C11: Recepción y verificación de envolvente (dimensiones, IP/IK, RAL) | D11: 1.5 | E11: Completado | F11: =IF($E11="N/A","",VLOOKUP($E11,AvanceTbl,2,FALSE())) -> 1 | K11: CSE
B12: 1.2 | C12: Ensamble de estructura y paneles del gabinete | D12: 5 | E12: Completado | F12: =IF($E12="N/A","",VLOOKUP($E12,AvanceTbl,2,FALSE())) -> 1 | K12: CMF
B13: 1.3 | C13: Montaje de perfilería DIN y placas de montaje | D13: 4 | E13: En proceso | F13: =IF($E13="N/A","",VLOOKUP($E13,AvanceTbl,2,FALSE())) -> 0.5 | K13: CMF
B14: 1.4 | C14: Instalación de puertas, bisagras y cerraduras | D14: 2 | E14: En proceso | F14: =IF($E14="N/A","",VLOOKUP($E14,AvanceTbl,2,FALSE())) -> 0.5 | K14: CMF
B15: 1.5 | C15: Fijación de canaletas y sistema de cableado | D15: 2.5 | E15: En proceso | F15: =IF($E15="N/A","",VLOOKUP($E15,AvanceTbl,2,FALSE())) -> 0.5 | K15: CSE
C16: 2. Montaje de protecciones | D16: =SUMIF($E17:$E22,"<>N/A",$D17:$D22) -> 10 | F16: {=IFERROR(SUMPRODUCT(($E17:$E22<>"N/A")*$D17:$D22,IF($E17:$E22="N/A",0,$F17:$F22))/$D16,0)} -> 0.825 | G16: 46274 | H16: 46275 | I16: 46206
B17: 2.1 | C17: Verificación de aparatos vs. lista de materiales (marca/In/Icu) | D17: 1.5 | E17: Completado | F17: =IF($E17="N/A","",VLOOKUP($E17,AvanceTbl,2,FALSE())) -> 1 | K17: CSE
B18: 2.2 | C18: Montaje de interruptor principal | D18: 3 | E18: Completado | F18: =IF($E18="N/A","",VLOOKUP($E18,AvanceTbl,2,FALSE())) -> 1 | K18: CMF
B19: 2.3 | C19: Montaje de protecciones de derivación | D19: 3 | E19: Completado | F19: =IF($E19="N/A","",VLOOKUP($E19,AvanceTbl,2,FALSE())) -> 1 | K19: CMF
B20: 2.4 | C20: Montaje de diferenciales / protecciones auxiliares | D20: 2 | E20: N/A | F20: =IF($E20="N/A","",VLOOKUP($E20,AvanceTbl,2,FALSE())) | K20: CMF
B21: 2.5 | C21: Instalación de instrumentación (medidores, TC, relés) | D21: 1.5 | E21: En proceso | F21: =IF($E21="N/A","",VLOOKUP($E21,AvanceTbl,2,FALSE())) -> 0.5 | K21: CMF
B22: 2.6 | C22: Fijación y torque de aparatos según layout | D22: 1 | E22: Pendiente | F22: =IF($E22="N/A","",VLOOKUP($E22,AvanceTbl,2,FALSE())) -> 0 | K22: CMF
C23: 3. Fabricación y montaje de barras | D23: =SUMIF($E24:$E29,"<>N/A",$D24:$D29) -> 28 | F23: {=IFERROR(SUMPRODUCT(($E24:$E29<>"N/A")*$D24:$D29,IF($E24:$E29="N/A",0,$F24:$F29))/$D23,0)} -> 0.85714286 | G23: 46274 | H23: 46275
B24: 3.1 | C24: Corte y conformado de barras (fases, N) | D24: 8 | E24: Completado | F24: =IF($E24="N/A","",VLOOKUP($E24,AvanceTbl,2,FALSE())) -> 1 | K24: CMF
B25: 3.2 | C25: Perforado y tratamiento de superficie / aislamiento | D25: 8 | E25: Completado | F25: =IF($E25="N/A","",VLOOKUP($E25,AvanceTbl,2,FALSE())) -> 1 | K25: CMF
B26: 3.3 | C26: Montaje de aisladores y soportes de barra | D26: 4 | E26: Completado | F26: =IF($E26="N/A","",VLOOKUP($E26,AvanceTbl,2,FALSE())) -> 1 | K26: CMF
B27: 3.4 | C27: Instalación de barras principales con torque especificado | D27: 4 | E27: Completado | F27: =IF($E27="N/A","",VLOOKUP($E27,AvanceTbl,2,FALSE())) -> 1 | K27: CMF
B28: 3.5 | C28: Montaje de barra de tierra (PE) y neutro (N) | D28: 2 | E28: Pendiente | F28: =IF($E28="N/A","",VLOOKUP($E28,AvanceTbl,2,FALSE())) -> 0 | K28: CMF
B29: 3.6 | C29: Conexión de derivaciones a protecciones | D29: 2 | E29: Pendiente | F29: =IF($E29="N/A","",VLOOKUP($E29,AvanceTbl,2,FALSE())) -> 0 | K29: CMF
C30: 4. Alambrado del tablero | D30: =SUMIF($E31:$E36,"<>N/A",$D31:$D36) -> 18 | F30: {=IFERROR(SUMPRODUCT(($E31:$E36<>"N/A")*$D31:$D36,IF($E31:$E36="N/A",0,$F31:$F36))/$D30,0)} -> 0.38888889 | G30: 46277 | H30: 46281
B31: 4.1 | C31: Alambrado de circuito de fuerza | D31: 4 | E31: En proceso | F31: =IF($E31="N/A","",VLOOKUP($E31,AvanceTbl,2,FALSE())) -> 0.5 | K31: CMF
B32: 4.2 | C32: Alambrado de circuito de control / mando | D32: 3 | E32: En proceso | F32: =IF($E32="N/A","",VLOOKUP($E32,AvanceTbl,2,FALSE())) -> 0.5 | K32: CMF
B33: 4.3 | C33: Conexionado de instrumentación y señalización | D33: 2 | E33: En proceso | F33: =IF($E33="N/A","",VLOOKUP($E33,AvanceTbl,2,FALSE())) -> 0.5 | K33: CMF
B34: 4.4 | C34: Montaje de punteras/terminales y apriete con torque | D34: 5 | E34: En proceso | F34: =IF($E34="N/A","",VLOOKUP($E34,AvanceTbl,2,FALSE())) -> 0.5 | K34: CMF
B35: 4.5 | C35: Peinado y ordenamiento de mazos de cable | D35: 2 | E35: Pendiente | F35: =IF($E35="N/A","",VLOOKUP($E35,AvanceTbl,2,FALSE())) -> 0 | K35: CMF
B36: 4.6 | C36: Conexión de barra PE a partes metálicas accesibles | D36: 2 | E36: Pendiente | F36: =IF($E36="N/A","",VLOOKUP($E36,AvanceTbl,2,FALSE())) -> 0 | K36: CMF
C37: 5. Rotulación | D37: =SUMIF($E38:$E42,"<>N/A",$D38:$D42) -> 5 | F37: {=IFERROR(SUMPRODUCT(($E38:$E42<>"N/A")*$D38:$D42,IF($E38:$E42="N/A",0,$F38:$F42))/$D37,0)} -> 0.15 | G37: 46282 | H37: 46282
B38: 5.1 | C38: Etiquetado de conductores en ambos extremos | D38: 1.5 | E38: En proceso | F38: =IF($E38="N/A","",VLOOKUP($E38,AvanceTbl,2,FALSE())) -> 0.5 | K38: CMF
B39: 5.2 | C39: Rotulado de aparatos y bornes según planos | D39: 1.5 | E39: Pendiente | F39: =IF($E39="N/A","",VLOOKUP($E39,AvanceTbl,2,FALSE())) -> 0 | K39: CMF
B40: 5.3 | C40: Instalación de placa de características (nameplate) | D40: 0.5 | E40: Pendiente | F40: =IF($E40="N/A","",VLOOKUP($E40,AvanceTbl,2,FALSE())) -> 0 | K40: CMF
B41: 5.4 | C41: Rótulos de advertencia y seguridad | D41: 0.5 | E41: Pendiente | F41: =IF($E41="N/A","",VLOOKUP($E41,AvanceTbl,2,FALSE())) -> 0 | K41: CMF
B42: 5.5 | C42: Verificación de coincidencia rótulos vs. esquema | D42: 1 | E42: Pendiente | F42: =IF($E42="N/A","",VLOOKUP($E42,AvanceTbl,2,FALSE())) -> 0 | K42: CSE
C43: 6. Pruebas FAT | D43: =SUMIF($E44:$E46,"<>N/A",$D44:$D46) -> 10 | F43: {=IFERROR(SUMPRODUCT(($E44:$E46<>"N/A")*$D44:$D46,IF($E44:$E46="N/A",0,$F44:$F46))/$D43,0)} -> 0 | G43: 46282 | H43: 46282
B44: 6.1 | C44: Ejecución de protocolo FAT (según alcance definido) | D44: 5 | E44: Pendiente | F44: =IF($E44="N/A","",VLOOKUP($E44,AvanceTbl,2,FALSE())) -> 0 | K44: CMF
...

Sheet BUS_B
B2: SEGUIMIENTO DE INTEGRACIÓN — TABLERO BUS_B
B4: Proyecto: | C4: REMODELACIÓN CENTRO DE DATOS MAGNUS 1 | F4: TAG: | G4: BUS_B | I4: Rev.:
B5: Fabricante: | C5: CMF | F5: OC/Contrato: | I5: Actualizado: | J5: 46234
B7: AVANCE GLOBAL DEL TABLERO | G7: =IFERROR(($D10*$F10+$D16*$F16+$D23*$F23+$D30*$F30+$D37*$F37+$D43*$F43+$D47*$F47+$D52*$F52)/($D10+$D16+$D23+$D30+$D37+$D43+$D47+$D52),0) -> 0.51785714
B9: # | C9: Hito / Sub-actividad | D9: Peso | E9: Estado | F9: Avance | G9: Plan Inicio | H9: Plan Fin | I9: Real Inicio | J9: Real Fin | K9: Responsable | L9: Observaciones
C10: 1. Armado de Tablero | D10: =SUMIF($E11:$E15,"<>N/A",$D11:$D15) -> 15 | F10: {=IFERROR(SUMPRODUCT(($E11:$E15<>"N/A")*$D11:$D15,IF($E11:$E15="N/A",0,$F11:$F15))/$D10,0)} -> 0.71666667 | G10: 46237 | H10: 46240 | I10: 46203 | J10: 46211
B11: 1.1 | C11: Recepción y verificación de envolvente (dimensiones, IP/IK, RAL) | D11: 1.5 | E11: Completado | F11: =IF($E11="N/A","",VLOOKUP($E11,AvanceTbl,2,FALSE())) -> 1 | K11: CSE
B12: 1.2 | C12: Ensamble de estructura y paneles del gabinete | D12: 5 | E12: Completado | F12: =IF($E12="N/A","",VLOOKUP($E12,AvanceTbl,2,FALSE())) -> 1 | K12: CMF
B13: 1.3 | C13: Montaje de perfilería DIN y placas de montaje | D13: 4 | E13: En proceso | F13: =IF($E13="N/A","",VLOOKUP($E13,AvanceTbl,2,FALSE())) -> 0.5 | K13: CMF
B14: 1.4 | C14: Instalación de puertas, bisagras y cerraduras | D14: 2 | E14: En proceso | F14: =IF($E14="N/A","",VLOOKUP($E14,AvanceTbl,2,FALSE())) -> 0.5 | K14: CMF
B15: 1.5 | C15: Fijación de canaletas y sistema de cableado | D15: 2.5 | E15: En proceso | F15: =IF($E15="N/A","",VLOOKUP($E15,AvanceTbl,2,FALSE())) -> 0.5 | K15: CSE
C16: 2. Montaje de protecciones | D16: =SUMIF($E17:$E22,"<>N/A",$D17:$D22) -> 10 | F16: {=IFERROR(SUMPRODUCT(($E17:$E22<>"N/A")*$D17:$D22,IF($E17:$E22="N/A",0,$F17:$F22))/$D16,0)} -> 0.825 | G16: 46274 | H16: 46275 | I16: 46206
B17: 2.1 | C17: Verificación de aparatos vs. lista de materiales (marca/In/Icu) | D17: 1.5 | E17: Completado | F17: =IF($E17="N/A","",VLOOKUP($E17,AvanceTbl,2,FALSE())) -> 1 | K17: CSE
B18: 2.2 | C18: Montaje de interruptor principal | D18: 3 | E18: Completado | F18: =IF($E18="N/A","",VLOOKUP($E18,AvanceTbl,2,FALSE())) -> 1 | K18: CMF
B19: 2.3 | C19: Montaje de protecciones de derivación | D19: 3 | E19: Completado | F19: =IF($E19="N/A","",VLOOKUP($E19,AvanceTbl,2,FALSE())) -> 1 | K19: CMF
B20: 2.4 | C20: Montaje de diferenciales / protecciones auxiliares | D20: 2 | E20: N/A | F20: =IF($E20="N/A","",VLOOKUP($E20,AvanceTbl,2,FALSE())) | K20: CMF
B21: 2.5 | C21: Instalación de instrumentación (medidores, TC, relés) | D21: 1.5 | E21: En proceso | F21: =IF($E21="N/A","",VLOOKUP($E21,AvanceTbl,2,FALSE())) -> 0.5 | K21: CMF
B22: 2.6 | C22: Fijación y torque de aparatos según layout | D22: 1 | E22: Pendiente | F22: =IF($E22="N/A","",VLOOKUP($E22,AvanceTbl,2,FALSE())) -> 0 | K22: CMF
C23: 3. Fabricación y montaje de barras | D23: =SUMIF($E24:$E29,"<>N/A",$D24:$D29) -> 28 | F23: {=IFERROR(SUMPRODUCT(($E24:$E29<>"N/A")*$D24:$D29,IF($E24:$E29="N/A",0,$F24:$F29))/$D23,0)} -> 0.85714286 | G23: 46274 | H23: 46275
B24: 3.1 | C24: Corte y conformado de barras (fases, N) | D24: 8 | E24: Completado | F24: =IF($E24="N/A","",VLOOKUP($E24,AvanceTbl,2,FALSE())) -> 1 | K24: CMF
B25: 3.2 | C25: Perforado y tratamiento de superficie / aislamiento | D25: 8 | E25: Completado | F25: =IF($E25="N/A","",VLOOKUP($E25,AvanceTbl,2,FALSE())) -> 1 | K25: CMF
B26: 3.3 | C26: Montaje de aisladores y soportes de barra | D26: 4 | E26: Completado | F26: =IF($E26="N/A","",VLOOKUP($E26,AvanceTbl,2,FALSE())) -> 1 | K26: CMF
B27: 3.4 | C27: Instalación de barras principales con torque especificado | D27: 4 | E27: Completado | F27: =IF($E27="N/A","",VLOOKUP($E27,AvanceTbl,2,FALSE())) -> 1 | K27: CMF
B28: 3.5 | C28: Montaje de barra de tierra (PE) y neutro (N) | D28: 2 | E28: Pendiente | F28: =IF($E28="N/A","",VLOOKUP($E28,AvanceTbl,2,FALSE())) -> 0 | K28: CMF
B29: 3.6 | C29: Conexión de derivaciones a protecciones | D29: 2 | E29: Pendiente | F29: =IF($E29="N/A","",VLOOKUP($E29,AvanceTbl,2,FALSE())) -> 0 | K29: CMF
C30: 4. Alambrado del tablero | D30: =SUMIF($E31:$E36,"<>N/A",$D31:$D36) -> 18 | F30: {=IFERROR(SUMPRODUCT(($E31:$E36<>"N/A")*$D31:$D36,IF($E31:$E36="N/A",0,$F31:$F36))/$D30,0)} -> 0.38888889 | G30: 46277 | H30: 46281
B31: 4.1 | C31: Alambrado de circuito de fuerza | D31: 4 | E31: En proceso | F31: =IF($E31="N/A","",VLOOKUP($E31,AvanceTbl,2,FALSE())) -> 0.5 | K31: CMF
B32: 4.2 | C32: Alambrado de circuito de control / mando | D32: 3 | E32: En proceso | F32: =IF($E32="N/A","",VLOOKUP($E32,AvanceTbl,2,FALSE())) -> 0.5 | K32: CMF
B33: 4.3 | C33: Conexionado de instrumentación y señalización | D33: 2 | E33: En proceso | F33: =IF($E33="N/A","",VLOOKUP($E33,AvanceTbl,2,FALSE())) -> 0.5 | K33: CMF
B34: 4.4 | C34: Montaje de punteras/terminales y apriete con torque | D34: 5 | E34: En proceso | F34: =IF($E34="N/A","",VLOOKUP($E34,AvanceTbl,2,FALSE())) -> 0.5 | K34: CMF
B35: 4.5 | C35: Peinado y ordenamiento de mazos de cable | D35: 2 | E35: Pendiente | F35: =IF($E35="N/A","",VLOOKUP($E35,AvanceTbl,2,FALSE())) -> 0 | K35: CMF
B36: 4.6 | C36: Conexión de barra PE a partes metálicas accesibles | D36: 2 | E36: Pendiente | F36: =IF($E36="N/A","",VLOOKUP($E36,AvanceTbl,2,FALSE())) -> 0 | K36: CMF
C37: 5. Rotulación | D37: =SUMIF($E38:$E42,"<>N/A",$D38:$D42) -> 5 | F37: {=IFERROR(SUMPRODUCT(($E38:$E42<>"N/A")*$D38:$D42,IF($E38:$E42="N/A",0,$F38:$F42))/$D37,0)} -> 0.15 | G37: 46282 | H37: 46282
B38: 5.1 | C38: Etiquetado de conductores en ambos extremos | D38: 1.5 | E38: En proceso | F38: =IF($E38="N/A","",VLOOKUP($E38,AvanceTbl,2,FALSE())) -> 0.5 | K38: CMF
B39: 5.2 | C39: Rotulado de aparatos y bornes según planos | D39: 1.5 | E39: Pendiente | F39: =IF($E39="N/A","",VLOOKUP($E39,AvanceTbl,2,FALSE())) -> 0 | K39: CMF
B40: 5.3 | C40: Instalación de placa de características (nameplate) | D40: 0.5 | E40: Pendiente | F40: =IF($E40="N/A","",VLOOKUP($E40,AvanceTbl,2,FALSE())) -> 0 | K40: CMF
B41: 5.4 | C41: Rótulos de advertencia y seguridad | D41: 0.5 | E41: Pendiente | F41: =IF($E41="N/A","",VLOOKUP($E41,AvanceTbl,2,FALSE())) -> 0 | K41: CMF
B42: 5.5 | C42: Verificación de coincidencia rótulos vs. esquema | D42: 1 | E42: Pendiente | F42: =IF($E42="N/A","",VLOOKUP($E42,AvanceTbl,2,FALSE())) -> 0 | K42: CSE
C43: 6. Pruebas FAT | D43: =SUMIF($E44:$E46,"<>N/A",$D44:$D46) -> 10 | F43: {=IFERROR(SUMPRODUCT(($E44:$E46<>"N/A")*$D44:$D46,IF($E44:$E46="N/A",0,$F44:$F46))/$D43,0)} -> 0 | G43: 46282 | H43: 46282
B44: 6.1 | C44: Ejecución de protocolo FAT (según alcance definido) | D44: 5 | E44: Pendiente | F44: =IF($E44="N/A","",VLOOKUP($E44,AvanceTbl,2,FALSE())) -> 0 | K44: CMF
...

Sheet CLIMA_A
B2: SEGUIMIENTO DE INTEGRACIÓN — TABLERO CLIMA_A
B4: Proyecto: | C4: REMODELACIÓN CENTRO DE DATOS MAGNUS 1 | F4: TAG: | G4: CLIMA_A | I4: Rev.:
B5: Fabricante: | C5: CMF | F5: OC/Contrato: | I5: Actualizado: | J5: 46234
B7: AVANCE GLOBAL DEL TABLERO | G7: =IFERROR(($D10*$F10+$D16*$F16+$D23*$F23+$D30*$F30+$D37*$F37+$D43*$F43+$D47*$F47+$D52*$F52)/($D10+$D16+$D23+$D30+$D37+$D43+$D47+$D52),0) -> 0.44836957
B9: # | C9: Hito / Sub-actividad | D9: Peso | E9: Estado | F9: Avance | G9: Plan Inicio | H9: Plan Fin | I9: Real Inicio | J9: Real Fin | K9: Responsable | L9: Observaciones
C10: 1. Armado de Tablero | D10: =SUMIF($E11:$E15,"<>N/A",$D11:$D15) -> 15 | F10: {=IFERROR(SUMPRODUCT(($E11:$E15<>"N/A")*$D11:$D15,IF($E11:$E15="N/A",0,$F11:$F15))/$D10,0)} -> 0.63333333 | G10: 46237 | H10: 46240
B11: 1.1 | C11: Recepción y verificación de envolvente (dimensiones, IP/IK, RAL) | D11: 1.5 | E11: Completado | F11: =IF($E11="N/A","",VLOOKUP($E11,AvanceTbl,2,FALSE())) -> 1 | K11: CSE
B12: 1.2 | C12: Ensamble de estructura y paneles del gabinete | D12: 5 | E12: Completado | F12: =IF($E12="N/A","",VLOOKUP($E12,AvanceTbl,2,FALSE())) -> 1 | K12: CMF
B13: 1.3 | C13: Montaje de perfilería DIN y placas de montaje | D13: 4 | E13: En proceso | F13: =IF($E13="N/A","",VLOOKUP($E13,AvanceTbl,2,FALSE())) -> 0.5 | K13: CMF
B14: 1.4 | C14: Instalación de puertas, bisagras y cerraduras | D14: 2 | E14: En proceso | F14: =IF($E14="N/A","",VLOOKUP($E14,AvanceTbl,2,FALSE())) -> 0.5 | K14: CMF
B15: 1.5 | C15: Fijación de canaletas y sistema de cableado | D15: 2.5 | E15: Pendiente | F15: =IF($E15="N/A","",VLOOKUP($E15,AvanceTbl,2,FALSE())) -> 0 | K15: CSE
C16: 2. Montaje de protecciones | D16: =SUMIF($E17:$E22,"<>N/A",$D17:$D22) -> 12 | F16: {=IFERROR(SUMPRODUCT(($E17:$E22<>"N/A")*$D17:$D22,IF($E17:$E22="N/A",0,$F17:$F22))/$D16,0)} -> 0.79166667 | G16: 46259 | H16: 46260
B17: 2.1 | C17: Verificación de aparatos vs. lista de materiales (marca/In/Icu) | D17: 1.5 | E17: Completado | F17: =IF($E17="N/A","",VLOOKUP($E17,AvanceTbl,2,FALSE())) -> 1 | K17: CSE
B18: 2.2 | C18: Montaje de interruptor principal | D18: 3 | E18: Completado | F18: =IF($E18="N/A","",VLOOKUP($E18,AvanceTbl,2,FALSE())) -> 1 | K18: CMF
B19: 2.3 | C19: Montaje de protecciones de derivación | D19: 3 | E19: Completado | F19: =IF($E19="N/A","",VLOOKUP($E19,AvanceTbl,2,FALSE())) -> 1 | K19: CMF
B20: 2.4 | C20: Montaje de diferenciales / protecciones auxiliares | D20: 2 | E20: Completado | F20: =IF($E20="N/A","",VLOOKUP($E20,AvanceTbl,2,FALSE())) -> 1 | K20: CMF
B21: 2.5 | C21: Instalación de instrumentación (medidores, TC, relés) | D21: 1.5 | E21: Pendiente | F21: =IF($E21="N/A","",VLOOKUP($E21,AvanceTbl,2,FALSE())) -> 0 | K21: CMF
B22: 2.6 | C22: Fijación y torque de aparatos según layout | D22: 1 | E22: Pendiente | F22: =IF($E22="N/A","",VLOOKUP($E22,AvanceTbl,2,FALSE())) -> 0 | K22: CMF
C23: 3. Fabricación y montaje de barras | D23: =SUMIF($E24:$E29,"<>N/A",$D24:$D29) -> 18 | F23: {=IFERROR(SUMPRODUCT(($E24:$E29<>"N/A")*$D24:$D29,IF($E24:$E29="N/A",0,$F24:$F29))/$D23,0)} -> 0.69444444 | G23: 46259 | H23: 46260
B24: 3.1 | C24: Corte y conformado de barras (fases, N) | D24: 4 | E24: Completado | F24: =IF($E24="N/A","",VLOOKUP($E24,AvanceTbl,2,FALSE())) -> 1 | K24: CMF
B25: 3.2 | C25: Perforado y tratamiento de superficie / aislamiento | D25: 3 | E25: Completado | F25: =IF($E25="N/A","",VLOOKUP($E25,AvanceTbl,2,FALSE())) -> 1 | K25: CMF
B26: 3.3 | C26: Montaje de aisladores y soportes de barra | D26: 2 | E26: Completado | F26: =IF($E26="N/A","",VLOOKUP($E26,AvanceTbl,2,FALSE())) -> 1 | K26: CMF
B27: 3.4 | C27: Instalación de barras principales con torque especificado | D27: 5 | E27: En proceso | F27: =IF($E27="N/A","",VLOOKUP($E27,AvanceTbl,2,FALSE())) -> 0.5 | K27: CMF
B28: 3.5 | C28: Montaje de barra de tierra (PE) y neutro (N) | D28: 2 | E28: Pendiente | F28: =IF($E28="N/A","",VLOOKUP($E28,AvanceTbl,2,FALSE())) -> 0 | K28: CMF
B29: 3.6 | C29: Conexión de derivaciones a protecciones | D29: 2 | E29: En proceso | F29: =IF($E29="N/A","",VLOOKUP($E29,AvanceTbl,2,FALSE())) -> 0.5 | K29: CMF
C30: 4. Alambrado del tablero | D30: =SUMIF($E31:$E36,"<>N/A",$D31:$D36) -> 20 | F30: {=IFERROR(SUMPRODUCT(($E31:$E36<>"N/A")*$D31:$D36,IF($E31:$E36="N/A",0,$F31:$F36))/$D30,0)} -> 0.45 | G30: 46262 | H30: 46266
B31: 4.1 | C31: Alambrado de circuito de fuerza | D31: 8 | E31: En proceso | F31: =IF($E31="N/A","",VLOOKUP($E31,AvanceTbl,2,FALSE())) -> 0.5 | K31: CMF
B32: 4.2 | C32: Alambrado de circuito de control / mando | D32: 8 | E32: N/A | F32: =IF($E32="N/A","",VLOOKUP($E32,AvanceTbl,2,FALSE())) | K32: CMF
B33: 4.3 | C33: Conexionado de instrumentación y señalización | D33: 4 | E33: En proceso | F33: =IF($E33="N/A","",VLOOKUP($E33,AvanceTbl,2,FALSE())) -> 0.5 | K33: CMF
B34: 4.4 | C34: Montaje de punteras/terminales y apriete con torque | D34: 4 | E34: En proceso | F34: =IF($E34="N/A","",VLOOKUP($E34,AvanceTbl,2,FALSE())) -> 0.5 | K34: CMF
B35: 4.5 | C35: Peinado y ordenamiento de mazos de cable | D35: 2 | E35: En proceso | F35: =IF($E35="N/A","",VLOOKUP($E35,AvanceTbl,2,FALSE())) -> 0.5 | K35: CMF
B36: 4.6 | C36: Conexión de barra PE a partes metálicas accesibles | D36: 2 | E36: Pendiente | F36: =IF($E36="N/A","",VLOOKUP($E36,AvanceTbl,2,FALSE())) -> 0 | K36: CMF
C37: 5. Rotulación | D37: =SUMIF($E38:$E42,"<>N/A",$D38:$D42) -> 5 | F37: {=IFERROR(SUMPRODUCT(($E38:$E42<>"N/A")*$D38:$D42,IF($E38:$E42="N/A",0,$F38:$F42))/$D37,0)} -> 0.15 | G37: 46267 | H37: 46267
B38: 5.1 | C38: Etiquetado de conductores en ambos extremos | D38: 1.5 | E38: En proceso | F38: =IF($E38="N/A","",VLOOKUP($E38,AvanceTbl,2,FALSE())) -> 0.5 | K38: CMF
B39: 5.2 | C39: Rotulado de aparatos y bornes según planos | D39: 1.5 | E39: Pendiente | F39: =IF($E39="N/A","",VLOOKUP($E39,AvanceTbl,2,FALSE())) -> 0 | K39: CMF
B40: 5.3 | C40: Instalación de placa de características (nameplate) | D40: 0.5 | E40: Pendiente | F40: =IF($E40="N/A","",VLOOKUP($E40,AvanceTbl,2,FALSE())) -> 0 | K40: CMF
B41: 5.4 | C41: Rótulos de advertencia y seguridad | D41: 0.5 | E41: Pendiente | F41: =IF($E41="N/A","",VLOOKUP($E41,AvanceTbl,2,FALSE())) -> 0 | K41: CMF
B42: 5.5 | C42: Verificación de coincidencia rótulos vs. esquema | D42: 1 | E42: Pendiente | F42: =IF($E42="N/A","",VLOOKUP($E42,AvanceTbl,2,FALSE())) -> 0 | K42: CSE
C43: 6. Pruebas FAT | D43: =SUMIF($E44:$E46,"<>N/A",$D44:$D46) -> 10 | F43: {=IFERROR(SUMPRODUCT(($E44:$E46<>"N/A")*$D44:$D46,IF($E44:$E46="N/A",0,$F44:$F46))/$D43,0)} -> 0 | G43: 46267 | H43: 46267
B44: 6.1 | C44: Ejecución de protocolo FAT (según alcance definido) | D44: 5 | E44: Pendiente | F44: =IF($E44="N/A","",VLOOKUP($E44,AvanceTbl,2,FALSE())) -> 0 | K44: CMF
...

Sheet CLIMA_B
B2: SEGUIMIENTO DE INTEGRACIÓN — TABLERO CLIMA_B
B4: Proyecto: | C4: REMODELACIÓN CENTRO DE DATOS MAGNUS 1 | F4: TAG: | G4: CLIMA_B | I4: Rev.:
B5: Fabricante: | C5: CMF | F5: OC/Contrato: | I5: Actualizado: | J5: 46234
B7: AVANCE GLOBAL DEL TABLERO | G7: =IFERROR(($D10*$F10+$D16*$F16+$D23*$F23+$D30*$F30+$D37*$F37+$D43*$F43+$D47*$F47+$D52*$F52)/($D10+$D16+$D23+$D30+$D37+$D43+$D47+$D52),0) -> 0.44836957
B9: # | C9: Hito / Sub-actividad | D9: Peso | E9: Estado | F9: Avance | G9: Plan Inicio | H9: Plan Fin | I9: Real Inicio | J9: Real Fin | K9: Responsable | L9: Observaciones
C10: 1. Armado de Tablero | D10: =SUMIF($E11:$E15,"<>N/A",$D11:$D15) -> 15 | F10: {=IFERROR(SUMPRODUCT(($E11:$E15<>"N/A")*$D11:$D15,IF($E11:$E15="N/A",0,$F11:$F15))/$D10,0)} -> 0.63333333 | G10: 46237 | H10: 46240
B11: 1.1 | C11: Recepción y verificación de envolvente (dimensiones, IP/IK, RAL) | D11: 1.5 | E11: Completado | F11: =IF($E11="N/A","",VLOOKUP($E11,AvanceTbl,2,FALSE())) -> 1 | K11: CSE
B12: 1.2 | C12: Ensamble de estructura y paneles del gabinete | D12: 5 | E12: Completado | F12: =IF($E12="N/A","",VLOOKUP($E12,AvanceTbl,2,FALSE())) -> 1 | K12: CMF
B13: 1.3 | C13: Montaje de perfilería DIN y placas de montaje | D13: 4 | E13: En proceso | F13: =IF($E13="N/A","",VLOOKUP($E13,AvanceTbl,2,FALSE())) -> 0.5 | K13: CMF
B14: 1.4 | C14: Instalación de puertas, bisagras y cerraduras | D14: 2 | E14: En proceso | F14: =IF($E14="N/A","",VLOOKUP($E14,AvanceTbl,2,FALSE())) -> 0.5 | K14: CMF
B15: 1.5 | C15: Fijación de canaletas y sistema de cableado | D15: 2.5 | E15: Pendiente | F15: =IF($E15="N/A","",VLOOKUP($E15,AvanceTbl,2,FALSE())) -> 0 | K15: CSE
C16: 2. Montaje de protecciones | D16: =SUMIF($E17:$E22,"<>N/A",$D17:$D22) -> 12 | F16: {=IFERROR(SUMPRODUCT(($E17:$E22<>"N/A")*$D17:$D22,IF($E17:$E22="N/A",0,$F17:$F22))/$D16,0)} -> 0.79166667 | G16: 46259 | H16: 46260
B17: 2.1 | C17: Verificación de aparatos vs. lista de materiales (marca/In/Icu) | D17: 1.5 | E17: Completado | F17: =IF($E17="N/A","",VLOOKUP($E17,AvanceTbl,2,FALSE())) -> 1 | K17: CSE
B18: 2.2 | C18: Montaje de interruptor principal | D18: 3 | E18: Completado | F18: =IF($E18="N/A","",VLOOKUP($E18,AvanceTbl,2,FALSE())) -> 1 | K18: CMF
B19: 2.3 | C19: Montaje de protecciones de derivación | D19: 3 | E19: Completado | F19: =IF($E19="N/A","",VLOOKUP($E19,AvanceTbl,2,FALSE())) -> 1 | K19: CMF
B20: 2.4 | C20: Montaje de diferenciales / protecciones auxiliares | D20: 2 | E20: Completado | F20: =IF($E20="N/A","",VLOOKUP($E20,AvanceTbl,2,FALSE())) -> 1 | K20: CMF
B21: 2.5 | C21: Instalación de instrumentación (medidores, TC, relés) | D21: 1.5 | E21: Pendiente | F21: =IF($E21="N/A","",VLOOKUP($E21,AvanceTbl,2,FALSE())) -> 0 | K21: CMF
B22: 2.6 | C22: Fijación y torque de aparatos según layout | D22: 1 | E22: Pendiente | F22: =IF($E22="N/A","",VLOOKUP($E22,AvanceTbl,2,FALSE())) -> 0 | K22: CMF
C23: 3. Fabricación y montaje de barras | D23: =SUMIF($E24:$E29,"<>N/A",$D24:$D29) -> 18 | F23: {=IFERROR(SUMPRODUCT(($E24:$E29<>"N/A")*$D24:$D29,IF($E24:$E29="N/A",0,$F24:$F29))/$D23,0)} -> 0.69444444 | G23: 46259 | H23: 46260
B24: 3.1 | C24: Corte y conformado de barras (fases, N) | D24: 4 | E24: Completado | F24: =IF($E24="N/A","",VLOOKUP($E24,AvanceTbl,2,FALSE())) -> 1 | K24: CMF
B25: 3.2 | C25: Perforado y tratamiento de superficie / aislamiento | D25: 3 | E25: Completado | F25: =IF($E25="N/A","",VLOOKUP($E25,AvanceTbl,2,FALSE())) -> 1 | K25: CMF
B26: 3.3 | C26: Montaje de aisladores y soportes de barra | D26: 2 | E26: Completado | F26: =IF($E26="N/A","",VLOOKUP($E26,AvanceTbl,2,FALSE())) -> 1 | K26: CMF
B27: 3.4 | C27: Instalación de barras principales con torque especificado | D27: 5 | E27: En proceso | F27: =IF($E27="N/A","",VLOOKUP($E27,AvanceTbl,2,FALSE())) -> 0.5 | K27: CMF
B28: 3.5 | C28: Montaje de barra de tierra (PE) y neutro (N) | D28: 2 | E28: Pendiente | F28: =IF($E28="N/A","",VLOOKUP($E28,AvanceTbl,2,FALSE())) -> 0 | K28: CMF
B29: 3.6 | C29: Conexión de derivaciones a protecciones | D29: 2 | E29: En proceso | F29: =IF($E29="N/A","",VLOOKUP($E29,AvanceTbl,2,FALSE())) -> 0.5 | K29: CMF
C30: 4. Alambrado del tablero | D30: =SUMIF($E31:$E36,"<>N/A",$D31:$D36) -> 20 | F30: {=IFERROR(SUMPRODUCT(($E31:$E36<>"N/A")*$D31:$D36,IF($E31:$E36="N/A",0,$F31:$F36))/$D30,0)} -> 0.45 | G30: 46262 | H30: 46266
B31: 4.1 | C31: Alambrado de circuito de fuerza | D31: 8 | E31: En proceso | F31: =IF($E31="N/A","",VLOOKUP($E31,AvanceTbl,2,FALSE())) -> 0.5 | K31: CMF
B32: 4.2 | C32: Alambrado de circuito de control / mando | D32: 8 | E32: N/A | F32: =IF($E32="N/A","",VLOOKUP($E32,AvanceTbl,2,FALSE())) | K32: CMF
B33: 4.3 | C33: Conexionado de instrumentación y señalización | D33: 4 | E33: En proceso | F33: =IF($E33="N/A","",VLOOKUP($E33,AvanceTbl,2,FALSE())) -> 0.5 | K33: CMF
B34: 4.4 | C34: Montaje de punteras/terminales y apriete con torque | D34: 4 | E34: En proceso | F34: =IF($E34="N/A","",VLOOKUP($E34,AvanceTbl,2,FALSE())) -> 0.5 | K34: CMF
B35: 4.5 | C35: Peinado y ordenamiento de mazos de cable | D35: 2 | E35: En proceso | F35: =IF($E35="N/A","",VLOOKUP($E35,AvanceTbl,2,FALSE())) -> 0.5 | K35: CMF
B36: 4.6 | C36: Conexión de barra PE a partes metálicas accesibles | D36: 2 | E36: Pendiente | F36: =IF($E36="N/A","",VLOOKUP($E36,AvanceTbl,2,FALSE())) -> 0 | K36: CMF
C37: 5. Rotulación | D37: =SUMIF($E38:$E42,"<>N/A",$D38:$D42) -> 5 | F37: {=IFERROR(SUMPRODUCT(($E38:$E42<>"N/A")*$D38:$D42,IF($E38:$E42="N/A",0,$F38:$F42))/$D37,0)} -> 0.15 | G37: 46267 | H37: 46267
B38: 5.1 | C38: Etiquetado de conductores en ambos extremos | D38: 1.5 | E38: En proceso | F38: =IF($E38="N/A","",VLOOKUP($E38,AvanceTbl,2,FALSE())) -> 0.5 | K38: CMF
B39: 5.2 | C39: Rotulado de aparatos y bornes según planos | D39: 1.5 | E39: Pendiente | F39: =IF($E39="N/A","",VLOOKUP($E39,AvanceTbl,2,FALSE())) -> 0 | K39: CMF
B40: 5.3 | C40: Instalación de placa de características (nameplate) | D40: 0.5 | E40: Pendiente | F40: =IF($E40="N/A","",VLOOKUP($E40,AvanceTbl,2,FALSE())) -> 0 | K40: CMF
B41: 5.4 | C41: Rótulos de advertencia y seguridad | D41: 0.5 | E41: Pendiente | F41: =IF($E41="N/A","",VLOOKUP($E41,AvanceTbl,2,FALSE())) -> 0 | K41: CMF
B42: 5.5 | C42: Verificación de coincidencia rótulos vs. esquema | D42: 1 | E42: Pendiente | F42: =IF($E42="N/A","",VLOOKUP($E42,AvanceTbl,2,FALSE())) -> 0 | K42: CSE
C43: 6. Pruebas FAT | D43: =SUMIF($E44:$E46,"<>N/A",$D44:$D46) -> 10 | F43: {=IFERROR(SUMPRODUCT(($E44:$E46<>"N/A")*$D44:$D46,IF($E44:$E46="N/A",0,$F44:$F46))/$D43,0)} -> 0 | G43: 46267 | H43: 46267
B44: 6.1 | C44: Ejecución de protocolo FAT (según alcance definido) | D44: 5 | E44: Pendiente | F44: =IF($E44="N/A","",VLOOKUP($E44,AvanceTbl,2,FALSE())) -> 0 | K44: CMF
...

Sheet NoConformidades
A1: REGISTRO DE NO CONFORMIDADES (NC)
A2: N° NC | B2: Fecha Detección | C2: Tablero | D2: Hito / Actividad | E2: Descripción de la NC | F2: Severidad | G2: Acción correctiva | H2: Estado | I2: Responsable | J2: Fecha Compromiso | K2: Fecha Cierre | L2: Evidencia/Ref. | M2: Días Abierta
A3: =IF(D3="","","NC-"&TEXT(ROW()-2,"000")) | M3: =IF(B3="","",IF(K3="",TODAY()-B3,K3-B3))
A4: =IF(D4="","","NC-"&TEXT(ROW()-4,"000")) | M4: =IF(B4="","",IF(K4="",TODAY()-B4,K4-B4))
A5: =IF(D5="","","NC-"&TEXT(ROW()-4,"000")) | M5: =IF(B5="","",IF(K5="",TODAY()-B5,K5-B5))
A6: =IF(D6="","","NC-"&TEXT(ROW()-4,"000")) | M6: =IF(B6="","",IF(K6="",TODAY()-B6,K6-B6))
A7: =IF(D7="","","NC-"&TEXT(ROW()-4,"000")) | M7: =IF(B7="","",IF(K7="",TODAY()-B7,K7-B7))
A8: =IF(D8="","","NC-"&TEXT(ROW()-4,"000")) | M8: =IF(B8="","",IF(K8="",TODAY()-B8,K8-B8))
A9: =IF(D9="","","NC-"&TEXT(ROW()-4,"000")) | M9: =IF(B9="","",IF(K9="",TODAY()-B9,K9-B9))
A10: =IF(D10="","","NC-"&TEXT(ROW()-4,"000")) | M10: =IF(B10="","",IF(K10="",TODAY()-B10,K10-B10))
A11: =IF(D11="","","NC-"&TEXT(ROW()-4,"000")) | M11: =IF(B11="","",IF(K11="",TODAY()-B11,K11-B11))
A12: =IF(D12="","","NC-"&TEXT(ROW()-4,"000")) | M12: =IF(B12="","",IF(K12="",TODAY()-B12,K12-B12))
A13: =IF(D13="","","NC-"&TEXT(ROW()-4,"000")) | M13: =IF(B13="","",IF(K13="",TODAY()-B13,K13-B13))
A14: =IF(D14="","","NC-"&TEXT(ROW()-4,"000")) | M14: =IF(B14="","",IF(K14="",TODAY()-B14,K14-B14))
A15: =IF(D15="","","NC-"&TEXT(ROW()-4,"000")) | M15: =IF(B15="","",IF(K15="",TODAY()-B15,K15-B15))
... A32: =IF(D32="","","NC-"&TEXT(ROW()-4,"000")) | M32: =IF(B32="","",IF(K32="",TODAY()-B32,K32-B32))

Sheet ControlCambios
B2: CONTROL DE CAMBIOS
B4: N° Cambio | C4: Fecha | D4: Tablero | E4: Descripción del cambio | F4: Motivo / Justificación | G4: Impacto (plazo/costo/alcance) | H4: Estado | I4: Solicitante | J4: Aprobado por | K4: Fecha Aprob. | L4: Observaciones
B5: =IF(E5="","","CC-"&TEXT(ROW()-4,"000")) -> CC-001 | C5: 46223 | D5: CLIMA_A | E5: Reducción del largo total | F5: Espacio de instalación con poca holgura | G5: Bajo-Medio | H5: Aprobado | I5: PM / Cliente | K5: 46230 | L5: Informe RFC 001
B6: =IF(E6="","","CC-"&TEXT(ROW()-4,"000")) -> CC-002 | C6: 46223 | D6: CLIMA_B | E6: Reducción del largo total | F6: Espacio de instalación con poca holgura | G6: Bajo-Medio | H6: Aprobado | I6: PM / Cliente | K6: 46230
B7: =IF(E7="","","CC-"&TEXT(ROW()-4,"000"))
B8: =IF(E8="","","CC-"&TEXT(ROW()-4,"000"))
B9: =IF(E9="","","CC-"&TEXT(ROW()-4,"000"))
B10: =IF(E10="","","CC-"&TEXT(ROW()-4,"000"))
B11: =IF(E11="","","CC-"&TEXT(ROW()-4,"000"))
B12: =IF(E12="","","CC-"&TEXT(ROW()-4,"000"))
B13: =IF(E13="","","CC-"&TEXT(ROW()-4,"000"))
B14: =IF(E14="","","CC-"&TEXT(ROW()-4,"000"))
B15: =IF(E15="","","CC-"&TEXT(ROW()-4,"000"))
B16: =IF(E16="","","CC-"&TEXT(ROW()-4,"000"))
B17: =IF(E17="","","CC-"&TEXT(ROW()-4,"000"))
B18: =IF(E18="","","CC-"&TEXT(ROW()-4,"000"))
... B29: =IF(E29="","","CC-"&TEXT(ROW()-4,"000"))

Sheet Config
B2: CONFIGURACIÓN
B4: Estados y valor de avance | J4: Tableros
B5: Estado | C5: Avance | J5: TP
B6: Pendiente | C6: 0 | J6: T_G2
B7: En proceso | C7: 0.5 | J7: BUS_A
B8: Completado | C8: 1 | J8: BUS_B
B9: N/A | J9: CLIMA_A
J10: CLIMA_B
B12: Severidad NC | E12: Estado NC | G12: Estado Cambio
B13: Menor | E13: Abierta | G13: Propuesto
B14: Mayor | E14: En análisis | G14: Aprobado
B15: Crítica | E15: En corrección | G15: Rechazado
E16: Cerrada | G16: Implementado
B19: Nota: no modificar los nombres de estado; las hojas los referencian por fórmula.
